<?xml version="1.0"?>
<robot xmlns:xacro="http://ros.org/wiki/xacro">

<xacro:macro name="manipulator" params="prefix">
    <!-- links: main serial chain -->
    <link name="${prefix}base_link" >
        <visual>
            <origin xyz="0 0 0" rpy="0 0 0"/>
            <geometry>
                <mesh filename="package://hiwin_ra620_1621_support/meshes/visual/base_link.stl" scale="0.001 0.001 0.001"/>
            </geometry>
            <material name="Black">
                <color rgba="0.0 0.0 0.0 1.0"/>
            </material>
        </visual>
        <collision>
            <origin xyz="0 0 0" rpy="0 0 0"/>
            <geometry>
                <mesh filename="package://hiwin_ra620_1621_support/meshes/collision/base_link.stl" scale="0.001 0.001 0.001"/>
            </geometry>
        </collision>
    </link>

    <link name="${prefix}link_1" >
        <visual>
            <origin xyz="0 0 0" rpy="0 0 0"/>
            <geometry>
                <mesh filename="package://hiwin_ra620_1621_support/meshes/visual/link_1.stl" scale="0.001 0.001 0.001"/>
            </geometry>
            <material name="LightGrey">
                <color rgba="0.999 0.999 0.999 1.0"/>
            </material>
        </visual>
        <collision>
            <origin xyz="0 0 0" rpy="0 0 0"/>
            <geometry>
                <mesh filename="package://hiwin_ra620_1621_support/meshes/collision/link_1.stl" scale="0.001 0.001 0.001"/>
            </geometry>
        </collision>
    </link>

    <link name="${prefix}link_2" >
        <visual>
            <origin xyz="0 0 0" rpy="0 0 0"/>
            <geometry>
                <mesh filename="package://hiwin_ra620_1621_support/meshes/visual/link_2.stl" scale="0.001 0.001 0.001"/>
            </geometry>
            <material name="LightGrey">
                <color rgba="0.999 0.999 0.999 1.0"/>
            </material>
        </visual>
        <collision>
            <origin xyz="0 0 0" rpy="0 0 0"/>
            <geometry>
                <mesh filename="package://hiwin_ra620_1621_support/meshes/collision/link_2.stl" scale="0.001 0.001 0.001"/>
            </geometry>
        </collision>
    </link>

    <link name="${prefix}link_3" >
        <visual>
            <origin xyz="0 0 0" rpy="0 0 0"/>
            <geometry>
                <mesh filename="package://hiwin_ra620_1621_support/meshes/visual/link_3.stl" scale="0.001 0.001 0.001"/>
            </geometry>
            <material name="LightGrey">
                <color rgba="0.999 0.999 0.999 1.0"/>
            </material>
        </visual>
        <collision>
            <origin xyz="0 0 0" rpy="0 0 0"/>
            <geometry>
                <mesh filename="package://hiwin_ra620_1621_support/meshes/collision/link_3.stl" scale="0.001 0.001 0.001"/>
            </geometry>
        </collision>
    </link>

    <link name="${prefix}link_4" >
        <visual>
            <origin xyz="0 0 0" rpy="0 0 0"/>
            <geometry>
                <mesh filename="package://hiwin_ra620_1621_support/meshes/visual/link_4.stl" scale="0.001 0.001 0.001"/>
            </geometry>
            <material name="LightGrey">
                <color rgba="0.999 0.999 0.999 1.0"/>
            </material>
        </visual>
        <collision>
            <origin xyz="0 0 0" rpy="0 0 0"/>
            <geometry>
                <mesh filename="package://hiwin_ra620_1621_support/meshes/collision/link_4.stl" scale="0.001 0.001 0.001"/>
            </geometry>
        </collision>
    </link>

    <link name="${prefix}link_5" >
        <visual>
            <origin xyz="0 0 0" rpy="${pi/2} 0 0"/>
            <geometry>
                <mesh filename="package://hiwin_ra620_1621_support/meshes/visual/link_5.stl" scale="0.001 0.001 0.001"/>
            </geometry>
            <material name="LightGrey">
                <color rgba="0.999 0.999 0.999 1.0"/>
            </material>
        </visual>
        <collision>
            <origin xyz="0 0 0" rpy="${pi/2} 0 0"/>
            <geometry>
                <mesh filename="package://hiwin_ra620_1621_support/meshes/collision/link_5.stl" scale="0.001 0.001 0.001"/>
            </geometry>
        </collision>
    </link>

    <link name="${prefix}link_6" >
        <visual>
            <origin xyz="0 0 0" rpy="${pi/2} 0 0"/>
            <geometry>
                <mesh filename="package://hiwin_ra620_1621_support/meshes/visual/link_6.stl" scale="0.001 0.001 0.001"/>
            </geometry>
            <material name="LightGrey">
                <color rgba="0.999 0.999 0.999 1.0"/>
            </material>
        </visual>
        <collision>
            <origin xyz="0 0 0" rpy="${pi/2} 0 0"/>
            <geometry>
                <mesh filename="package://hiwin_ra620_1621_support/meshes/collision/link_6.stl" scale="0.001 0.001 0.001"/>
            </geometry>
        </collision>
    </link>

    <!-- joints: main serial chain -->
    <joint name="${prefix}joint_1" type="revolute">
        <origin xyz="0.0 0.0 0.245" rpy="0.0 0.0 0.0" />
        <parent link="${prefix}base_link" />
        <child link="${prefix}link_1" />
        <axis xyz="0 0 1" />
        <limit lower="${-pi/2}" upper="${pi/2}" effort="0" velocity="2.018"/>
    </joint>

    <joint name="${prefix}joint_2" type="revolute">
        <origin xyz="0.106 0.150 0.280" rpy="0.0 0.0 0.0" />
        <parent link="${prefix}link_1" />
        <child link="${prefix}link_2" />
        <axis xyz="1 0 0" />
        <limit lower="${-pi*135/180}" upper="${pi*100/180}" effort="0" velocity="2.018"/>
    </joint>

    <joint name="${prefix}joint_3" type="revolute">
        <origin xyz="0.0385 0.0 0.770" rpy="0.0 0.0 0.0" />
        <parent link="${prefix}link_2" />
        <child link="${prefix}link_3" />
        <axis xyz="1 0 0" />
        <limit lower="${-pi*80/180}" upper="${pi*190/180}" effort="0" velocity="2.018"/>
    </joint>

    <joint name="${prefix}joint_4" type="revolute">
        <origin xyz="-0.1445 0.231 0.150" rpy="0.0 0.0 0.0" />
        <parent link="${prefix}link_3" />
        <child link="${prefix}link_4" />
        <axis xyz="0 1 0" />
        <limit lower="${-pi*200/180}" upper="${pi*200/180}" effort="0" velocity="2.018"/>
    </joint>

    <joint name="${prefix}joint_5" type="revolute">
        <origin xyz="0.0 0.454 0.0" rpy="0.0 0.0 0.0" />
        <parent link="${prefix}link_4" />
        <child link="${prefix}link_5" />
        <axis xyz="1 0 0" />
        <limit lower="${-pi*130/180}" upper="${pi*130/180}" effort="0" velocity="2.018"/>
    </joint>

    <joint name="${prefix}joint_6" type="revolute">
        <origin xyz="0.0 0.0885 0.0" rpy="0.0 0.0 0.0" />
        <parent link="${prefix}link_5" />
        <child link="${prefix}link_6" />
        <axis xyz="0 1 0" />
        <limit lower="${-pi}" upper="${pi}" effort="0" velocity="2.018"/>
    </joint>

    <!-- ROS-Industrial 'base' frame: base_link to HIWIN World Coordinates transform -->
    <link name="${prefix}base" />
    <joint name="${prefix}base_link-base" type="fixed">
      <origin xyz="0.0 0.0 0.525" rpy="0 0 0"/>
      <parent link="${prefix}base_link"/>
      <child link="${prefix}base"/>
    </joint>

    <!-- ROS-Industrial 'flange' frame: attachment point for EEF models -->
    <link name="${prefix}flange" />
    <joint name="${prefix}joint_6-flange" type="fixed">
      <origin xyz="0 0.0215 0" rpy="0 0 0" />
      <parent link="${prefix}link_6" />
      <child link="${prefix}flange" />
    </joint>

    <!-- ROS-Industrial 'tool0' frame: all-zeros tool frame -->
    <link name="${prefix}tool0" />
    <joint name="${prefix}link_6-tool0" type="fixed">
      <origin xyz="0 0.1215 0.0" rpy="0.0 ${-pi/2.0} ${-pi/2.0}" />
      <parent link="${prefix}link_6" />
      <child link="${prefix}tool0" />
    </joint>
    
  </xacro:macro>
</robot>
